/Users/kimya/.pyenv/versions/3.7.3/bin/python: can't open file '/Users/kimya/Documents/GitHub/Predix/manage.py': [Errno 1] Operation not permitted
/Users/kimya/.pyenv/versions/3.7.3/bin/python: can't open file '/Users/kimya/Documents/GitHub/Predix/manage.py': [Errno 1] Operation not permitted
/Users/kimya/.pyenv/versions/3.7.3/bin/python: can't open file '/Users/kimya/Documents/GitHub/Predix/manage.py': [Errno 1] Operation not permitted
/Users/kimya/.pyenv/versions/3.7.3/bin/python: can't open file '/Users/kimya/Documents/GitHub/Predix/manage.py': [Errno 1] Operation not permitted
/Users/kimya/.pyenv/versions/3.7.3/bin/python: can't open file '/Users/kimya/Documents/GitHub/Predix/manage.py': [Errno 1] Operation not permitted
/Users/kimya/.pyenv/versions/3.7.3/bin/python: can't open file '/Users/kimya/Documents/GitHub/Predix/manage.py': [Errno 1] Operation not permitted
/Users/kimya/.pyenv/versions/3.7.3/bin/python: can't open file '/Users/kimya/Documents/GitHub/Predix/manage.py': [Errno 1] Operation not permitted
/Users/kimya/.pyenv/versions/3.7.3/bin/python: can't open file '/Users/kimya/Documents/GitHub/Predix/manage.py': [Errno 1] Operation not permitted
/Users/kimya/.pyenv/versions/3.7.3/bin/python: can't open file '/Users/kimya/Documents/GitHub/Predix/manage.py': [Errno 1] Operation not permitted
/Users/kimya/.pyenv/versions/3.7.3/bin/python: can't open file '/Users/kimya/Documents/GitHub/Predix/manage.py': [Errno 1] Operation not permitted
/Users/kimya/.pyenv/versions/3.7.3/bin/python: can't open file '/Users/kimya/Documents/GitHub/Predix/manage.py': [Errno 1] Operation not permitted
/Users/kimya/.pyenv/versions/3.7.3/bin/python: can't open file '/Users/kimya/Documents/GitHub/Predix/manage.py': [Errno 1] Operation not permitted
/Users/kimya/.pyenv/versions/3.7.3/bin/python: can't open file '/Users/kimya/Documents/GitHub/Predix/manage.py': [Errno 1] Operation not permitted
/Users/kimya/.pyenv/versions/3.7.3/bin/python: can't open file '/Users/kimya/Documents/GitHub/Predix/manage.py': [Errno 1] Operation not permitted
/Users/kimya/.pyenv/versions/3.7.3/bin/python: can't open file '/Users/kimya/Documents/GitHub/Predix/manage.py': [Errno 1] Operation not permitted
/Users/kimya/.pyenv/versions/3.7.3/bin/python: can't open file '/Users/kimya/Documents/GitHub/Predix/manage.py': [Errno 1] Operation not permitted
/Users/kimya/.pyenv/versions/3.7.3/bin/python: can't open file '/Users/kimya/Documents/GitHub/Predix/manage.py': [Errno 1] Operation not permitted
/Users/kimya/.pyenv/versions/3.7.3/bin/python: can't open file '/Users/kimya/Documents/GitHub/Predix/manage.py': [Errno 1] Operation not permitted
/Users/kimya/.pyenv/versions/3.7.3/bin/python: can't open file '/Users/kimya/Documents/GitHub/Predix/manage.py': [Errno 1] Operation not permitted
/Users/kimya/.pyenv/versions/3.7.3/bin/python: can't open file '/Users/kimya/Documents/GitHub/Predix/manage.py': [Errno 1] Operation not permitted
/Users/kimya/.pyenv/versions/3.7.3/bin/python: can't open file '/Users/kimya/Documents/GitHub/Predix/manage.py': [Errno 1] Operation not permitted
/Users/kimya/.pyenv/versions/3.7.3/bin/python: can't open file '/Users/kimya/Documents/GitHub/Predix/manage.py': [Errno 1] Operation not permitted
/Users/kimya/.pyenv/versions/3.7.3/bin/python: can't open file '/Users/kimya/Documents/GitHub/Predix/manage.py': [Errno 1] Operation not permitted
/Users/kimya/.pyenv/versions/3.7.3/bin/python: can't open file '/Users/kimya/Documents/GitHub/Predix/manage.py': [Errno 1] Operation not permitted
/Users/kimya/.pyenv/versions/3.7.3/bin/python: can't open file '/Users/kimya/Documents/GitHub/Predix/manage.py': [Errno 1] Operation not permitted
/Users/kimya/.pyenv/versions/3.7.3/bin/python: can't open file '/Users/kimya/Documents/GitHub/Predix/manage.py': [Errno 1] Operation not permitted
/Users/kimya/.pyenv/versions/3.7.3/bin/python: can't open file '/Users/kimya/Documents/GitHub/Predix/manage.py': [Errno 1] Operation not permitted
/Users/kimya/.pyenv/versions/3.7.3/bin/python: can't open file '/Users/kimya/Documents/GitHub/Predix/manage.py': [Errno 1] Operation not permitted
/Users/kimya/.pyenv/versions/3.7.3/bin/python: can't open file '/Users/kimya/Documents/GitHub/Predix/manage.py': [Errno 1] Operation not permitted
/Users/kimya/.pyenv/versions/3.7.3/bin/python: can't open file '/Users/kimya/Documents/GitHub/Predix/manage.py': [Errno 1] Operation not permitted
/Users/kimya/.pyenv/versions/3.7.3/bin/python: can't open file '/Users/kimya/Documents/GitHub/Predix/manage.py': [Errno 1] Operation not permitted
/Users/kimya/.pyenv/versions/3.7.3/bin/python: can't open file '/Users/kimya/Documents/GitHub/Predix/manage.py': [Errno 1] Operation not permitted
/Users/kimya/.pyenv/versions/3.7.3/bin/python: can't open file '/Users/kimya/Documents/GitHub/Predix/manage.py': [Errno 1] Operation not permitted
/Users/kimya/.pyenv/versions/3.7.3/bin/python: can't open file '/Users/kimya/Documents/GitHub/Predix/manage.py': [Errno 1] Operation not permitted
/Users/kimya/.pyenv/versions/3.7.3/bin/python: can't open file '/Users/kimya/Documents/GitHub/Predix/manage.py': [Errno 1] Operation not permitted
/Users/kimya/.pyenv/versions/3.7.3/bin/python: can't open file '/Users/kimya/Documents/GitHub/Predix/manage.py': [Errno 1] Operation not permitted
/Users/kimya/.pyenv/versions/3.7.3/bin/python: can't open file '/Users/kimya/Documents/GitHub/Predix/manage.py': [Errno 1] Operation not permitted
/Users/kimya/.pyenv/versions/3.7.3/bin/python: can't open file '/Users/kimya/Documents/GitHub/Predix/manage.py': [Errno 1] Operation not permitted
/Users/kimya/.pyenv/versions/3.7.3/bin/python: can't open file '/Users/kimya/Documents/GitHub/Predix/manage.py': [Errno 1] Operation not permitted
/Users/kimya/.pyenv/versions/3.7.3/bin/python: can't open file '/Users/kimya/Documents/GitHub/Predix/manage.py': [Errno 1] Operation not permitted
/Users/kimya/.pyenv/versions/3.7.3/bin/python: can't open file '/Users/kimya/Documents/GitHub/Predix/manage.py': [Errno 1] Operation not permitted
/Users/kimya/.pyenv/versions/3.7.3/bin/python: can't open file '/Users/kimya/Documents/GitHub/Predix/manage.py': [Errno 1] Operation not permitted
/Users/kimya/.pyenv/versions/3.7.3/bin/python: can't open file '/Users/kimya/Documents/GitHub/Predix/manage.py': [Errno 1] Operation not permitted
/Users/kimya/.pyenv/versions/3.7.3/bin/python: can't open file '/Users/kimya/Documents/GitHub/Predix/manage.py': [Errno 1] Operation not permitted
/Users/kimya/.pyenv/versions/3.7.3/bin/python: can't open file '/Users/kimya/Documents/GitHub/Predix/manage.py': [Errno 1] Operation not permitted
/Users/kimya/.pyenv/versions/3.7.3/bin/python: can't open file '/Users/kimya/Documents/GitHub/Predix/manage.py': [Errno 1] Operation not permitted
/Users/kimya/.pyenv/versions/3.7.3/bin/python: can't open file '/Users/kimya/Documents/GitHub/Predix/manage.py': [Errno 1] Operation not permitted
/Users/kimya/.pyenv/versions/3.7.3/bin/python: can't open file '/Users/kimya/Documents/GitHub/Predix/manage.py': [Errno 1] Operation not permitted
/Users/kimya/.pyenv/versions/3.7.3/bin/python: can't open file '/Users/kimya/Documents/GitHub/Predix/manage.py': [Errno 1] Operation not permitted
/Users/kimya/.pyenv/versions/3.7.3/bin/python: can't open file '/Users/kimya/Documents/GitHub/Predix/manage.py': [Errno 1] Operation not permitted
/Users/kimya/.pyenv/versions/3.7.3/bin/python: can't open file '/Users/kimya/Documents/GitHub/Predix/manage.py': [Errno 1] Operation not permitted
/Users/kimya/.pyenv/versions/3.7.3/bin/python: can't open file '/Users/kimya/Documents/GitHub/Predix/manage.py': [Errno 1] Operation not permitted
/Users/kimya/.pyenv/versions/3.7.3/bin/python: can't open file '/Users/kimya/Documents/GitHub/Predix/manage.py': [Errno 1] Operation not permitted
/Users/kimya/.pyenv/versions/3.7.3/bin/python: can't open file '/Users/kimya/Documents/GitHub/Predix/manage.py': [Errno 1] Operation not permitted
/Users/kimya/.pyenv/versions/3.7.3/bin/python: can't open file '/Users/kimya/Documents/GitHub/Predix/manage.py': [Errno 1] Operation not permitted
/Users/kimya/.pyenv/versions/3.7.3/bin/python: can't open file '/Users/kimya/Documents/GitHub/Predix/manage.py': [Errno 1] Operation not permitted
/Users/kimya/.pyenv/versions/3.7.3/bin/python: can't open file '/Users/kimya/Documents/GitHub/Predix/manage.py': [Errno 1] Operation not permitted
/Users/kimya/.pyenv/versions/3.7.3/bin/python: can't open file '/Users/kimya/Documents/GitHub/Predix/manage.py': [Errno 1] Operation not permitted
/Users/kimya/.pyenv/versions/3.7.3/bin/python: can't open file '/Users/kimya/Documents/GitHub/Predix/manage.py': [Errno 1] Operation not permitted
/Users/kimya/.pyenv/versions/3.7.3/bin/python: can't open file '/Users/kimya/Documents/GitHub/Predix/manage.py': [Errno 1] Operation not permitted
/Users/kimya/.pyenv/versions/3.7.3/bin/python: can't open file '/Users/kimya/Documents/GitHub/Predix/manage.py': [Errno 1] Operation not permitted
/Users/kimya/.pyenv/versions/3.7.3/bin/python: can't open file '/Users/kimya/Documents/GitHub/Predix/manage.py': [Errno 1] Operation not permitted
/Users/kimya/.pyenv/versions/3.7.3/bin/python: can't open file '/Users/kimya/Documents/GitHub/Predix/manage.py': [Errno 1] Operation not permitted
/Users/kimya/.pyenv/versions/3.7.3/bin/python: can't open file '/Users/kimya/Documents/GitHub/Predix/manage.py': [Errno 1] Operation not permitted
/Users/kimya/.pyenv/versions/3.7.3/bin/python: can't open file '/Users/kimya/Documents/GitHub/Predix/manage.py': [Errno 1] Operation not permitted
/Users/kimya/.pyenv/versions/3.7.3/bin/python: can't open file '/Users/kimya/Documents/GitHub/Predix/manage.py': [Errno 1] Operation not permitted
/Users/kimya/.pyenv/versions/3.7.3/bin/python: can't open file '/Users/kimya/Documents/GitHub/Predix/manage.py': [Errno 1] Operation not permitted
/Users/kimya/.pyenv/versions/3.7.3/bin/python: can't open file '/Users/kimya/Documents/GitHub/Predix/manage.py': [Errno 1] Operation not permitted
/Users/kimya/.pyenv/versions/3.7.3/bin/python: can't open file '/Users/kimya/Documents/GitHub/Predix/manage.py': [Errno 1] Operation not permitted
/Users/kimya/.pyenv/versions/3.7.3/bin/python: can't open file '/Users/kimya/Documents/GitHub/Predix/manage.py': [Errno 1] Operation not permitted
/Users/kimya/.pyenv/versions/3.7.3/bin/python: can't open file '/Users/kimya/Documents/GitHub/Predix/manage.py': [Errno 1] Operation not permitted
/Users/kimya/.pyenv/versions/3.7.3/bin/python: can't open file '/Users/kimya/Documents/GitHub/Predix/manage.py': [Errno 1] Operation not permitted
/Users/kimya/.pyenv/versions/3.7.3/bin/python: can't open file '/Users/kimya/Documents/GitHub/Predix/manage.py': [Errno 1] Operation not permitted
/Users/kimya/.pyenv/versions/3.7.3/bin/python: can't open file '/Users/kimya/Documents/GitHub/Predix/manage.py': [Errno 1] Operation not permitted
/Users/kimya/.pyenv/versions/3.7.3/bin/python: can't open file '/Users/kimya/Documents/GitHub/Predix/manage.py': [Errno 1] Operation not permitted
/Users/kimya/.pyenv/versions/3.7.3/bin/python: can't open file '/Users/kimya/Documents/GitHub/Predix/manage.py': [Errno 1] Operation not permitted
/Users/kimya/.pyenv/versions/3.7.3/bin/python: can't open file '/Users/kimya/Documents/GitHub/Predix/manage.py': [Errno 1] Operation not permitted
/Users/kimya/.pyenv/versions/3.7.3/bin/python: can't open file '/Users/kimya/Documents/GitHub/Predix/manage.py': [Errno 1] Operation not permitted
/Users/kimya/.pyenv/versions/3.7.3/bin/python: can't open file '/Users/kimya/Documents/GitHub/Predix/manage.py': [Errno 1] Operation not permitted
/Users/kimya/.pyenv/versions/3.7.3/bin/python: can't open file '/Users/kimya/Documents/GitHub/Predix/manage.py': [Errno 1] Operation not permitted
/Users/kimya/.pyenv/versions/3.7.3/bin/python: can't open file '/Users/kimya/Documents/GitHub/Predix/manage.py': [Errno 1] Operation not permitted
aaaa
Traceback (most recent call last):
  File "/Users/kimya/Documents/GitHub/Predix/manage.py", line 22, in <module>
    main()
  File "/Users/kimya/Documents/GitHub/Predix/manage.py", line 18, in main
    execute_from_command_line(sys.argv)
  File "/Users/kimya/.pyenv/versions/3.7.3/lib/python3.7/site-packages/django/core/management/__init__.py", line 419, in execute_from_command_line
    utility.execute()
  File "/Users/kimya/.pyenv/versions/3.7.3/lib/python3.7/site-packages/django/core/management/__init__.py", line 413, in execute
    self.fetch_command(subcommand).run_from_argv(self.argv)
  File "/Users/kimya/.pyenv/versions/3.7.3/lib/python3.7/site-packages/django/core/management/__init__.py", line 257, in fetch_command
    klass = load_command_class(app_name, subcommand)
  File "/Users/kimya/.pyenv/versions/3.7.3/lib/python3.7/site-packages/django/core/management/__init__.py", line 39, in load_command_class
    module = import_module('%s.management.commands.%s' % (app_name, name))
  File "/Users/kimya/.pyenv/versions/3.7.3/lib/python3.7/importlib/__init__.py", line 127, in import_module
    return _bootstrap._gcd_import(name[level:], package, level)
  File "<frozen importlib._bootstrap>", line 1006, in _gcd_import
  File "<frozen importlib._bootstrap>", line 983, in _find_and_load
  File "<frozen importlib._bootstrap>", line 967, in _find_and_load_unlocked
  File "<frozen importlib._bootstrap>", line 677, in _load_unlocked
  File "<frozen importlib._bootstrap_external>", line 724, in exec_module
  File "<frozen importlib._bootstrap_external>", line 860, in get_code
  File "<frozen importlib._bootstrap_external>", line 791, in source_to_code
  File "<frozen importlib._bootstrap>", line 219, in _call_with_frames_removed
  File "/Users/kimya/Documents/GitHub/Predix/crypto/management/commands/mycommand.py", line 16
    file1.close()
        ^
SyntaxError: invalid syntax
aaaa
aaaa
aaaa
aaaa
aaaa
aaaa
aaaa
aaaa
aaaa
aaaa
aaaa
aaaa
aaaa
aaaa
aaaa
Traceback (most recent call last):
  File "/Users/kimya/.pyenv/versions/3.7.3/lib/python3.7/site-packages/urllib3/connection.py", line 170, in _new_conn
    (self._dns_host, self.port), self.timeout, **extra_kw
  File "/Users/kimya/.pyenv/versions/3.7.3/lib/python3.7/site-packages/urllib3/util/connection.py", line 73, in create_connection
    for res in socket.getaddrinfo(host, port, family, socket.SOCK_STREAM):
  File "/Users/kimya/.pyenv/versions/3.7.3/lib/python3.7/socket.py", line 748, in getaddrinfo
    for res in _socket.getaddrinfo(host, port, family, type, proto, flags):
socket.gaierror: [Errno 8] nodename nor servname provided, or not known

During handling of the above exception, another exception occurred:

Traceback (most recent call last):
  File "/Users/kimya/.pyenv/versions/3.7.3/lib/python3.7/site-packages/urllib3/connectionpool.py", line 706, in urlopen
    chunked=chunked,
  File "/Users/kimya/.pyenv/versions/3.7.3/lib/python3.7/site-packages/urllib3/connectionpool.py", line 382, in _make_request
    self._validate_conn(conn)
  File "/Users/kimya/.pyenv/versions/3.7.3/lib/python3.7/site-packages/urllib3/connectionpool.py", line 1010, in _validate_conn
    conn.connect()
  File "/Users/kimya/.pyenv/versions/3.7.3/lib/python3.7/site-packages/urllib3/connection.py", line 353, in connect
    conn = self._new_conn()
  File "/Users/kimya/.pyenv/versions/3.7.3/lib/python3.7/site-packages/urllib3/connection.py", line 182, in _new_conn
    self, "Failed to establish a new connection: %s" % e
urllib3.exceptions.NewConnectionError: <urllib3.connection.HTTPSConnection object at 0x1051a7160>: Failed to establish a new connection: [Errno 8] nodename nor servname provided, or not known

During handling of the above exception, another exception occurred:

Traceback (most recent call last):
  File "/Users/kimya/.pyenv/versions/3.7.3/lib/python3.7/site-packages/requests/adapters.py", line 449, in send
    timeout=timeout
  File "/Users/kimya/.pyenv/versions/3.7.3/lib/python3.7/site-packages/urllib3/connectionpool.py", line 756, in urlopen
    method, url, error=e, _pool=self, _stacktrace=sys.exc_info()[2]
  File "/Users/kimya/.pyenv/versions/3.7.3/lib/python3.7/site-packages/urllib3/util/retry.py", line 574, in increment
    raise MaxRetryError(_pool, url, error or ResponseError(cause))
urllib3.exceptions.MaxRetryError: HTTPSConnectionPool(host='pro-api.coinmarketcap.com', port=443): Max retries exceeded with url: /v1/cryptocurrency/listings/latest?start=1&limit=50&convert=USD (Caused by NewConnectionError('<urllib3.connection.HTTPSConnection object at 0x1051a7160>: Failed to establish a new connection: [Errno 8] nodename nor servname provided, or not known'))

During handling of the above exception, another exception occurred:

Traceback (most recent call last):
  File "/Users/kimya/Documents/GitHub/Predix/manage.py", line 22, in <module>
    main()
  File "/Users/kimya/Documents/GitHub/Predix/manage.py", line 18, in main
    execute_from_command_line(sys.argv)
  File "/Users/kimya/.pyenv/versions/3.7.3/lib/python3.7/site-packages/django/core/management/__init__.py", line 419, in execute_from_command_line
    utility.execute()
  File "/Users/kimya/.pyenv/versions/3.7.3/lib/python3.7/site-packages/django/core/management/__init__.py", line 413, in execute
    self.fetch_command(subcommand).run_from_argv(self.argv)
  File "/Users/kimya/.pyenv/versions/3.7.3/lib/python3.7/site-packages/django/core/management/base.py", line 354, in run_from_argv
    self.execute(*args, **cmd_options)
  File "/Users/kimya/.pyenv/versions/3.7.3/lib/python3.7/site-packages/django/core/management/base.py", line 398, in execute
    output = self.handle(*args, **options)
  File "/Users/kimya/Documents/GitHub/Predix/crypto/management/commands/mycommand.py", line 19, in handle
    json = requests.get(url, params=params, headers=headers).json()
  File "/Users/kimya/.pyenv/versions/3.7.3/lib/python3.7/site-packages/requests/api.py", line 76, in get
    return request('get', url, params=params, **kwargs)
  File "/Users/kimya/.pyenv/versions/3.7.3/lib/python3.7/site-packages/requests/api.py", line 61, in request
    return session.request(method=method, url=url, **kwargs)
  File "/Users/kimya/.pyenv/versions/3.7.3/lib/python3.7/site-packages/requests/sessions.py", line 542, in request
    resp = self.send(prep, **send_kwargs)
  File "/Users/kimya/.pyenv/versions/3.7.3/lib/python3.7/site-packages/requests/sessions.py", line 655, in send
    r = adapter.send(request, **kwargs)
  File "/Users/kimya/.pyenv/versions/3.7.3/lib/python3.7/site-packages/requests/adapters.py", line 516, in send
    raise ConnectionError(e, request=request)
requests.exceptions.ConnectionError: HTTPSConnectionPool(host='pro-api.coinmarketcap.com', port=443): Max retries exceeded with url: /v1/cryptocurrency/listings/latest?start=1&limit=50&convert=USD (Caused by NewConnectionError('<urllib3.connection.HTTPSConnection object at 0x1051a7160>: Failed to establish a new connection: [Errno 8] nodename nor servname provided, or not known'))
Traceback (most recent call last):
  File "/Users/kimya/.pyenv/versions/3.7.3/lib/python3.7/site-packages/urllib3/connection.py", line 170, in _new_conn
    (self._dns_host, self.port), self.timeout, **extra_kw
  File "/Users/kimya/.pyenv/versions/3.7.3/lib/python3.7/site-packages/urllib3/util/connection.py", line 73, in create_connection
    for res in socket.getaddrinfo(host, port, family, socket.SOCK_STREAM):
  File "/Users/kimya/.pyenv/versions/3.7.3/lib/python3.7/socket.py", line 748, in getaddrinfo
    for res in _socket.getaddrinfo(host, port, family, type, proto, flags):
socket.gaierror: [Errno 8] nodename nor servname provided, or not known

During handling of the above exception, another exception occurred:

Traceback (most recent call last):
  File "/Users/kimya/.pyenv/versions/3.7.3/lib/python3.7/site-packages/urllib3/connectionpool.py", line 706, in urlopen
    chunked=chunked,
  File "/Users/kimya/.pyenv/versions/3.7.3/lib/python3.7/site-packages/urllib3/connectionpool.py", line 382, in _make_request
    self._validate_conn(conn)
  File "/Users/kimya/.pyenv/versions/3.7.3/lib/python3.7/site-packages/urllib3/connectionpool.py", line 1010, in _validate_conn
    conn.connect()
  File "/Users/kimya/.pyenv/versions/3.7.3/lib/python3.7/site-packages/urllib3/connection.py", line 353, in connect
    conn = self._new_conn()
  File "/Users/kimya/.pyenv/versions/3.7.3/lib/python3.7/site-packages/urllib3/connection.py", line 182, in _new_conn
    self, "Failed to establish a new connection: %s" % e
urllib3.exceptions.NewConnectionError: <urllib3.connection.HTTPSConnection object at 0x10e188208>: Failed to establish a new connection: [Errno 8] nodename nor servname provided, or not known

During handling of the above exception, another exception occurred:

Traceback (most recent call last):
  File "/Users/kimya/.pyenv/versions/3.7.3/lib/python3.7/site-packages/requests/adapters.py", line 449, in send
    timeout=timeout
  File "/Users/kimya/.pyenv/versions/3.7.3/lib/python3.7/site-packages/urllib3/connectionpool.py", line 756, in urlopen
    method, url, error=e, _pool=self, _stacktrace=sys.exc_info()[2]
  File "/Users/kimya/.pyenv/versions/3.7.3/lib/python3.7/site-packages/urllib3/util/retry.py", line 574, in increment
    raise MaxRetryError(_pool, url, error or ResponseError(cause))
urllib3.exceptions.MaxRetryError: HTTPSConnectionPool(host='pro-api.coinmarketcap.com', port=443): Max retries exceeded with url: /v1/cryptocurrency/listings/latest?start=1&limit=50&convert=USD (Caused by NewConnectionError('<urllib3.connection.HTTPSConnection object at 0x10e188208>: Failed to establish a new connection: [Errno 8] nodename nor servname provided, or not known'))

During handling of the above exception, another exception occurred:

Traceback (most recent call last):
  File "/Users/kimya/Documents/GitHub/Predix/manage.py", line 22, in <module>
    main()
  File "/Users/kimya/Documents/GitHub/Predix/manage.py", line 18, in main
    execute_from_command_line(sys.argv)
  File "/Users/kimya/.pyenv/versions/3.7.3/lib/python3.7/site-packages/django/core/management/__init__.py", line 419, in execute_from_command_line
    utility.execute()
  File "/Users/kimya/.pyenv/versions/3.7.3/lib/python3.7/site-packages/django/core/management/__init__.py", line 413, in execute
    self.fetch_command(subcommand).run_from_argv(self.argv)
  File "/Users/kimya/.pyenv/versions/3.7.3/lib/python3.7/site-packages/django/core/management/base.py", line 354, in run_from_argv
    self.execute(*args, **cmd_options)
  File "/Users/kimya/.pyenv/versions/3.7.3/lib/python3.7/site-packages/django/core/management/base.py", line 398, in execute
    output = self.handle(*args, **options)
  File "/Users/kimya/Documents/GitHub/Predix/crypto/management/commands/mycommand.py", line 19, in handle
    json = requests.get(url, params=params, headers=headers).json()
  File "/Users/kimya/.pyenv/versions/3.7.3/lib/python3.7/site-packages/requests/api.py", line 76, in get
    return request('get', url, params=params, **kwargs)
  File "/Users/kimya/.pyenv/versions/3.7.3/lib/python3.7/site-packages/requests/api.py", line 61, in request
    return session.request(method=method, url=url, **kwargs)
  File "/Users/kimya/.pyenv/versions/3.7.3/lib/python3.7/site-packages/requests/sessions.py", line 542, in request
    resp = self.send(prep, **send_kwargs)
  File "/Users/kimya/.pyenv/versions/3.7.3/lib/python3.7/site-packages/requests/sessions.py", line 655, in send
    r = adapter.send(request, **kwargs)
  File "/Users/kimya/.pyenv/versions/3.7.3/lib/python3.7/site-packages/requests/adapters.py", line 516, in send
    raise ConnectionError(e, request=request)
requests.exceptions.ConnectionError: HTTPSConnectionPool(host='pro-api.coinmarketcap.com', port=443): Max retries exceeded with url: /v1/cryptocurrency/listings/latest?start=1&limit=50&convert=USD (Caused by NewConnectionError('<urllib3.connection.HTTPSConnection object at 0x10e188208>: Failed to establish a new connection: [Errno 8] nodename nor servname provided, or not known'))
Traceback (most recent call last):
  File "/Users/kimya/.pyenv/versions/3.7.3/lib/python3.7/site-packages/urllib3/connection.py", line 170, in _new_conn
    (self._dns_host, self.port), self.timeout, **extra_kw
  File "/Users/kimya/.pyenv/versions/3.7.3/lib/python3.7/site-packages/urllib3/util/connection.py", line 73, in create_connection
    for res in socket.getaddrinfo(host, port, family, socket.SOCK_STREAM):
  File "/Users/kimya/.pyenv/versions/3.7.3/lib/python3.7/socket.py", line 748, in getaddrinfo
    for res in _socket.getaddrinfo(host, port, family, type, proto, flags):
socket.gaierror: [Errno 8] nodename nor servname provided, or not known

During handling of the above exception, another exception occurred:

Traceback (most recent call last):
  File "/Users/kimya/.pyenv/versions/3.7.3/lib/python3.7/site-packages/urllib3/connectionpool.py", line 706, in urlopen
    chunked=chunked,
  File "/Users/kimya/.pyenv/versions/3.7.3/lib/python3.7/site-packages/urllib3/connectionpool.py", line 382, in _make_request
    self._validate_conn(conn)
  File "/Users/kimya/.pyenv/versions/3.7.3/lib/python3.7/site-packages/urllib3/connectionpool.py", line 1010, in _validate_conn
    conn.connect()
  File "/Users/kimya/.pyenv/versions/3.7.3/lib/python3.7/site-packages/urllib3/connection.py", line 353, in connect
    conn = self._new_conn()
  File "/Users/kimya/.pyenv/versions/3.7.3/lib/python3.7/site-packages/urllib3/connection.py", line 182, in _new_conn
    self, "Failed to establish a new connection: %s" % e
urllib3.exceptions.NewConnectionError: <urllib3.connection.HTTPSConnection object at 0x1037a7240>: Failed to establish a new connection: [Errno 8] nodename nor servname provided, or not known

During handling of the above exception, another exception occurred:

Traceback (most recent call last):
  File "/Users/kimya/.pyenv/versions/3.7.3/lib/python3.7/site-packages/requests/adapters.py", line 449, in send
    timeout=timeout
  File "/Users/kimya/.pyenv/versions/3.7.3/lib/python3.7/site-packages/urllib3/connectionpool.py", line 756, in urlopen
    method, url, error=e, _pool=self, _stacktrace=sys.exc_info()[2]
  File "/Users/kimya/.pyenv/versions/3.7.3/lib/python3.7/site-packages/urllib3/util/retry.py", line 574, in increment
    raise MaxRetryError(_pool, url, error or ResponseError(cause))
urllib3.exceptions.MaxRetryError: HTTPSConnectionPool(host='pro-api.coinmarketcap.com', port=443): Max retries exceeded with url: /v1/cryptocurrency/listings/latest?start=1&limit=50&convert=USD (Caused by NewConnectionError('<urllib3.connection.HTTPSConnection object at 0x1037a7240>: Failed to establish a new connection: [Errno 8] nodename nor servname provided, or not known'))

During handling of the above exception, another exception occurred:

Traceback (most recent call last):
  File "/Users/kimya/Documents/GitHub/Predix/manage.py", line 22, in <module>
    main()
  File "/Users/kimya/Documents/GitHub/Predix/manage.py", line 18, in main
    execute_from_command_line(sys.argv)
  File "/Users/kimya/.pyenv/versions/3.7.3/lib/python3.7/site-packages/django/core/management/__init__.py", line 419, in execute_from_command_line
    utility.execute()
  File "/Users/kimya/.pyenv/versions/3.7.3/lib/python3.7/site-packages/django/core/management/__init__.py", line 413, in execute
    self.fetch_command(subcommand).run_from_argv(self.argv)
  File "/Users/kimya/.pyenv/versions/3.7.3/lib/python3.7/site-packages/django/core/management/base.py", line 354, in run_from_argv
    self.execute(*args, **cmd_options)
  File "/Users/kimya/.pyenv/versions/3.7.3/lib/python3.7/site-packages/django/core/management/base.py", line 398, in execute
    output = self.handle(*args, **options)
  File "/Users/kimya/Documents/GitHub/Predix/crypto/management/commands/mycommand.py", line 19, in handle
    json = requests.get(url, params=params, headers=headers).json()
  File "/Users/kimya/.pyenv/versions/3.7.3/lib/python3.7/site-packages/requests/api.py", line 76, in get
    return request('get', url, params=params, **kwargs)
  File "/Users/kimya/.pyenv/versions/3.7.3/lib/python3.7/site-packages/requests/api.py", line 61, in request
    return session.request(method=method, url=url, **kwargs)
  File "/Users/kimya/.pyenv/versions/3.7.3/lib/python3.7/site-packages/requests/sessions.py", line 542, in request
    resp = self.send(prep, **send_kwargs)
  File "/Users/kimya/.pyenv/versions/3.7.3/lib/python3.7/site-packages/requests/sessions.py", line 655, in send
    r = adapter.send(request, **kwargs)
  File "/Users/kimya/.pyenv/versions/3.7.3/lib/python3.7/site-packages/requests/adapters.py", line 516, in send
    raise ConnectionError(e, request=request)
requests.exceptions.ConnectionError: HTTPSConnectionPool(host='pro-api.coinmarketcap.com', port=443): Max retries exceeded with url: /v1/cryptocurrency/listings/latest?start=1&limit=50&convert=USD (Caused by NewConnectionError('<urllib3.connection.HTTPSConnection object at 0x1037a7240>: Failed to establish a new connection: [Errno 8] nodename nor servname provided, or not known'))
Traceback (most recent call last):
  File "/Users/kimya/.pyenv/versions/3.7.3/lib/python3.7/site-packages/urllib3/connection.py", line 170, in _new_conn
    (self._dns_host, self.port), self.timeout, **extra_kw
  File "/Users/kimya/.pyenv/versions/3.7.3/lib/python3.7/site-packages/urllib3/util/connection.py", line 73, in create_connection
    for res in socket.getaddrinfo(host, port, family, socket.SOCK_STREAM):
  File "/Users/kimya/.pyenv/versions/3.7.3/lib/python3.7/socket.py", line 748, in getaddrinfo
    for res in _socket.getaddrinfo(host, port, family, type, proto, flags):
socket.gaierror: [Errno 8] nodename nor servname provided, or not known

During handling of the above exception, another exception occurred:

Traceback (most recent call last):
  File "/Users/kimya/.pyenv/versions/3.7.3/lib/python3.7/site-packages/urllib3/connectionpool.py", line 706, in urlopen
    chunked=chunked,
  File "/Users/kimya/.pyenv/versions/3.7.3/lib/python3.7/site-packages/urllib3/connectionpool.py", line 382, in _make_request
    self._validate_conn(conn)
  File "/Users/kimya/.pyenv/versions/3.7.3/lib/python3.7/site-packages/urllib3/connectionpool.py", line 1010, in _validate_conn
    conn.connect()
  File "/Users/kimya/.pyenv/versions/3.7.3/lib/python3.7/site-packages/urllib3/connection.py", line 353, in connect
    conn = self._new_conn()
  File "/Users/kimya/.pyenv/versions/3.7.3/lib/python3.7/site-packages/urllib3/connection.py", line 182, in _new_conn
    self, "Failed to establish a new connection: %s" % e
urllib3.exceptions.NewConnectionError: <urllib3.connection.HTTPSConnection object at 0x10becd240>: Failed to establish a new connection: [Errno 8] nodename nor servname provided, or not known

During handling of the above exception, another exception occurred:

Traceback (most recent call last):
  File "/Users/kimya/.pyenv/versions/3.7.3/lib/python3.7/site-packages/requests/adapters.py", line 449, in send
    timeout=timeout
  File "/Users/kimya/.pyenv/versions/3.7.3/lib/python3.7/site-packages/urllib3/connectionpool.py", line 756, in urlopen
    method, url, error=e, _pool=self, _stacktrace=sys.exc_info()[2]
  File "/Users/kimya/.pyenv/versions/3.7.3/lib/python3.7/site-packages/urllib3/util/retry.py", line 574, in increment
    raise MaxRetryError(_pool, url, error or ResponseError(cause))
urllib3.exceptions.MaxRetryError: HTTPSConnectionPool(host='pro-api.coinmarketcap.com', port=443): Max retries exceeded with url: /v1/cryptocurrency/listings/latest?start=1&limit=50&convert=USD (Caused by NewConnectionError('<urllib3.connection.HTTPSConnection object at 0x10becd240>: Failed to establish a new connection: [Errno 8] nodename nor servname provided, or not known'))

During handling of the above exception, another exception occurred:

Traceback (most recent call last):
  File "/Users/kimya/Documents/GitHub/Predix/manage.py", line 22, in <module>
    main()
  File "/Users/kimya/Documents/GitHub/Predix/manage.py", line 18, in main
    execute_from_command_line(sys.argv)
  File "/Users/kimya/.pyenv/versions/3.7.3/lib/python3.7/site-packages/django/core/management/__init__.py", line 419, in execute_from_command_line
    utility.execute()
  File "/Users/kimya/.pyenv/versions/3.7.3/lib/python3.7/site-packages/django/core/management/__init__.py", line 413, in execute
    self.fetch_command(subcommand).run_from_argv(self.argv)
  File "/Users/kimya/.pyenv/versions/3.7.3/lib/python3.7/site-packages/django/core/management/base.py", line 354, in run_from_argv
    self.execute(*args, **cmd_options)
  File "/Users/kimya/.pyenv/versions/3.7.3/lib/python3.7/site-packages/django/core/management/base.py", line 398, in execute
    output = self.handle(*args, **options)
  File "/Users/kimya/Documents/GitHub/Predix/crypto/management/commands/mycommand.py", line 19, in handle
    json = requests.get(url, params=params, headers=headers).json()
  File "/Users/kimya/.pyenv/versions/3.7.3/lib/python3.7/site-packages/requests/api.py", line 76, in get
    return request('get', url, params=params, **kwargs)
  File "/Users/kimya/.pyenv/versions/3.7.3/lib/python3.7/site-packages/requests/api.py", line 61, in request
    return session.request(method=method, url=url, **kwargs)
  File "/Users/kimya/.pyenv/versions/3.7.3/lib/python3.7/site-packages/requests/sessions.py", line 542, in request
    resp = self.send(prep, **send_kwargs)
  File "/Users/kimya/.pyenv/versions/3.7.3/lib/python3.7/site-packages/requests/sessions.py", line 655, in send
    r = adapter.send(request, **kwargs)
  File "/Users/kimya/.pyenv/versions/3.7.3/lib/python3.7/site-packages/requests/adapters.py", line 516, in send
    raise ConnectionError(e, request=request)
requests.exceptions.ConnectionError: HTTPSConnectionPool(host='pro-api.coinmarketcap.com', port=443): Max retries exceeded with url: /v1/cryptocurrency/listings/latest?start=1&limit=50&convert=USD (Caused by NewConnectionError('<urllib3.connection.HTTPSConnection object at 0x10becd240>: Failed to establish a new connection: [Errno 8] nodename nor servname provided, or not known'))
Traceback (most recent call last):
  File "/Users/kimya/.pyenv/versions/3.7.3/lib/python3.7/site-packages/urllib3/connection.py", line 170, in _new_conn
    (self._dns_host, self.port), self.timeout, **extra_kw
  File "/Users/kimya/.pyenv/versions/3.7.3/lib/python3.7/site-packages/urllib3/util/connection.py", line 73, in create_connection
    for res in socket.getaddrinfo(host, port, family, socket.SOCK_STREAM):
  File "/Users/kimya/.pyenv/versions/3.7.3/lib/python3.7/socket.py", line 748, in getaddrinfo
    for res in _socket.getaddrinfo(host, port, family, type, proto, flags):
socket.gaierror: [Errno 8] nodename nor servname provided, or not known

During handling of the above exception, another exception occurred:

Traceback (most recent call last):
  File "/Users/kimya/.pyenv/versions/3.7.3/lib/python3.7/site-packages/urllib3/connectionpool.py", line 706, in urlopen
    chunked=chunked,
  File "/Users/kimya/.pyenv/versions/3.7.3/lib/python3.7/site-packages/urllib3/connectionpool.py", line 382, in _make_request
    self._validate_conn(conn)
  File "/Users/kimya/.pyenv/versions/3.7.3/lib/python3.7/site-packages/urllib3/connectionpool.py", line 1010, in _validate_conn
    conn.connect()
  File "/Users/kimya/.pyenv/versions/3.7.3/lib/python3.7/site-packages/urllib3/connection.py", line 353, in connect
    conn = self._new_conn()
  File "/Users/kimya/.pyenv/versions/3.7.3/lib/python3.7/site-packages/urllib3/connection.py", line 182, in _new_conn
    self, "Failed to establish a new connection: %s" % e
urllib3.exceptions.NewConnectionError: <urllib3.connection.HTTPSConnection object at 0x109309208>: Failed to establish a new connection: [Errno 8] nodename nor servname provided, or not known

During handling of the above exception, another exception occurred:

Traceback (most recent call last):
  File "/Users/kimya/.pyenv/versions/3.7.3/lib/python3.7/site-packages/requests/adapters.py", line 449, in send
    timeout=timeout
  File "/Users/kimya/.pyenv/versions/3.7.3/lib/python3.7/site-packages/urllib3/connectionpool.py", line 756, in urlopen
    method, url, error=e, _pool=self, _stacktrace=sys.exc_info()[2]
  File "/Users/kimya/.pyenv/versions/3.7.3/lib/python3.7/site-packages/urllib3/util/retry.py", line 574, in increment
    raise MaxRetryError(_pool, url, error or ResponseError(cause))
urllib3.exceptions.MaxRetryError: HTTPSConnectionPool(host='pro-api.coinmarketcap.com', port=443): Max retries exceeded with url: /v1/cryptocurrency/listings/latest?start=1&limit=50&convert=USD (Caused by NewConnectionError('<urllib3.connection.HTTPSConnection object at 0x109309208>: Failed to establish a new connection: [Errno 8] nodename nor servname provided, or not known'))

During handling of the above exception, another exception occurred:

Traceback (most recent call last):
  File "/Users/kimya/Documents/GitHub/Predix/manage.py", line 22, in <module>
    main()
  File "/Users/kimya/Documents/GitHub/Predix/manage.py", line 18, in main
    execute_from_command_line(sys.argv)
  File "/Users/kimya/.pyenv/versions/3.7.3/lib/python3.7/site-packages/django/core/management/__init__.py", line 419, in execute_from_command_line
    utility.execute()
  File "/Users/kimya/.pyenv/versions/3.7.3/lib/python3.7/site-packages/django/core/management/__init__.py", line 413, in execute
    self.fetch_command(subcommand).run_from_argv(self.argv)
  File "/Users/kimya/.pyenv/versions/3.7.3/lib/python3.7/site-packages/django/core/management/base.py", line 354, in run_from_argv
    self.execute(*args, **cmd_options)
  File "/Users/kimya/.pyenv/versions/3.7.3/lib/python3.7/site-packages/django/core/management/base.py", line 398, in execute
    output = self.handle(*args, **options)
  File "/Users/kimya/Documents/GitHub/Predix/crypto/management/commands/mycommand.py", line 19, in handle
    json = requests.get(url, params=params, headers=headers).json()
  File "/Users/kimya/.pyenv/versions/3.7.3/lib/python3.7/site-packages/requests/api.py", line 76, in get
    return request('get', url, params=params, **kwargs)
  File "/Users/kimya/.pyenv/versions/3.7.3/lib/python3.7/site-packages/requests/api.py", line 61, in request
    return session.request(method=method, url=url, **kwargs)
  File "/Users/kimya/.pyenv/versions/3.7.3/lib/python3.7/site-packages/requests/sessions.py", line 542, in request
    resp = self.send(prep, **send_kwargs)
  File "/Users/kimya/.pyenv/versions/3.7.3/lib/python3.7/site-packages/requests/sessions.py", line 655, in send
    r = adapter.send(request, **kwargs)
  File "/Users/kimya/.pyenv/versions/3.7.3/lib/python3.7/site-packages/requests/adapters.py", line 516, in send
    raise ConnectionError(e, request=request)
requests.exceptions.ConnectionError: HTTPSConnectionPool(host='pro-api.coinmarketcap.com', port=443): Max retries exceeded with url: /v1/cryptocurrency/listings/latest?start=1&limit=50&convert=USD (Caused by NewConnectionError('<urllib3.connection.HTTPSConnection object at 0x109309208>: Failed to establish a new connection: [Errno 8] nodename nor servname provided, or not known'))
inside
inside
inside
inside
inside
inside
inside
inside
inside
Traceback (most recent call last):
  File "/Users/kimya/Documents/GitHub/Predix/manage.py", line 22, in <module>
    main()
  File "/Users/kimya/Documents/GitHub/Predix/manage.py", line 18, in main
    execute_from_command_line(sys.argv)
  File "/Users/kimya/.pyenv/versions/3.7.3/lib/python3.7/site-packages/django/core/management/__init__.py", line 419, in execute_from_command_line
    utility.execute()
  File "/Users/kimya/.pyenv/versions/3.7.3/lib/python3.7/site-packages/django/core/management/__init__.py", line 413, in execute
    self.fetch_command(subcommand).run_from_argv(self.argv)
  File "/Users/kimya/.pyenv/versions/3.7.3/lib/python3.7/site-packages/django/core/management/base.py", line 354, in run_from_argv
    self.execute(*args, **cmd_options)
  File "/Users/kimya/.pyenv/versions/3.7.3/lib/python3.7/site-packages/django/core/management/base.py", line 393, in execute
    self.check()
  File "/Users/kimya/.pyenv/versions/3.7.3/lib/python3.7/site-packages/django/core/management/base.py", line 423, in check
    databases=databases,
  File "/Users/kimya/.pyenv/versions/3.7.3/lib/python3.7/site-packages/django/core/checks/registry.py", line 76, in run_checks
    new_errors = check(app_configs=app_configs, databases=databases)
  File "/Users/kimya/.pyenv/versions/3.7.3/lib/python3.7/site-packages/django/core/checks/urls.py", line 13, in check_url_config
    return check_resolver(resolver)
  File "/Users/kimya/.pyenv/versions/3.7.3/lib/python3.7/site-packages/django/core/checks/urls.py", line 23, in check_resolver
    return check_method()
  File "/Users/kimya/.pyenv/versions/3.7.3/lib/python3.7/site-packages/django/urls/resolvers.py", line 412, in check
    for pattern in self.url_patterns:
  File "/Users/kimya/.pyenv/versions/3.7.3/lib/python3.7/site-packages/django/utils/functional.py", line 48, in __get__
    res = instance.__dict__[self.name] = self.func(instance)
  File "/Users/kimya/.pyenv/versions/3.7.3/lib/python3.7/site-packages/django/urls/resolvers.py", line 598, in url_patterns
    patterns = getattr(self.urlconf_module, "urlpatterns", self.urlconf_module)
  File "/Users/kimya/.pyenv/versions/3.7.3/lib/python3.7/site-packages/django/utils/functional.py", line 48, in __get__
    res = instance.__dict__[self.name] = self.func(instance)
  File "/Users/kimya/.pyenv/versions/3.7.3/lib/python3.7/site-packages/django/urls/resolvers.py", line 591, in urlconf_module
    return import_module(self.urlconf_name)
  File "/Users/kimya/.pyenv/versions/3.7.3/lib/python3.7/importlib/__init__.py", line 127, in import_module
    return _bootstrap._gcd_import(name[level:], package, level)
  File "<frozen importlib._bootstrap>", line 1006, in _gcd_import
  File "<frozen importlib._bootstrap>", line 983, in _find_and_load
  File "<frozen importlib._bootstrap>", line 967, in _find_and_load_unlocked
  File "<frozen importlib._bootstrap>", line 677, in _load_unlocked
  File "<frozen importlib._bootstrap_external>", line 728, in exec_module
  File "<frozen importlib._bootstrap>", line 219, in _call_with_frames_removed
  File "/Users/kimya/Documents/GitHub/Predix/predix/urls.py", line 23, in <module>
    path('crypto/', include('crypto.urls')),
  File "/Users/kimya/.pyenv/versions/3.7.3/lib/python3.7/site-packages/django/urls/conf.py", line 34, in include
    urlconf_module = import_module(urlconf_module)
  File "/Users/kimya/.pyenv/versions/3.7.3/lib/python3.7/importlib/__init__.py", line 127, in import_module
    return _bootstrap._gcd_import(name[level:], package, level)
  File "<frozen importlib._bootstrap>", line 1006, in _gcd_import
  File "<frozen importlib._bootstrap>", line 983, in _find_and_load
  File "<frozen importlib._bootstrap>", line 967, in _find_and_load_unlocked
  File "<frozen importlib._bootstrap>", line 677, in _load_unlocked
  File "<frozen importlib._bootstrap_external>", line 728, in exec_module
  File "<frozen importlib._bootstrap>", line 219, in _call_with_frames_removed
  File "/Users/kimya/Documents/GitHub/Predix/crypto/urls.py", line 5, in <module>
    from . import views
  File "/Users/kimya/Documents/GitHub/Predix/crypto/views.py", line 125
    liked = False
    ^
IndentationError: unexpected indent
Traceback (most recent call last):
  File "/Users/kimya/Documents/GitHub/Predix/manage.py", line 22, in <module>
    main()
  File "/Users/kimya/Documents/GitHub/Predix/manage.py", line 18, in main
    execute_from_command_line(sys.argv)
  File "/Users/kimya/.pyenv/versions/3.7.3/lib/python3.7/site-packages/django/core/management/__init__.py", line 419, in execute_from_command_line
    utility.execute()
  File "/Users/kimya/.pyenv/versions/3.7.3/lib/python3.7/site-packages/django/core/management/__init__.py", line 413, in execute
    self.fetch_command(subcommand).run_from_argv(self.argv)
  File "/Users/kimya/.pyenv/versions/3.7.3/lib/python3.7/site-packages/django/core/management/base.py", line 354, in run_from_argv
    self.execute(*args, **cmd_options)
  File "/Users/kimya/.pyenv/versions/3.7.3/lib/python3.7/site-packages/django/core/management/base.py", line 393, in execute
    self.check()
  File "/Users/kimya/.pyenv/versions/3.7.3/lib/python3.7/site-packages/django/core/management/base.py", line 423, in check
    databases=databases,
  File "/Users/kimya/.pyenv/versions/3.7.3/lib/python3.7/site-packages/django/core/checks/registry.py", line 76, in run_checks
    new_errors = check(app_configs=app_configs, databases=databases)
  File "/Users/kimya/.pyenv/versions/3.7.3/lib/python3.7/site-packages/django/core/checks/urls.py", line 13, in check_url_config
    return check_resolver(resolver)
  File "/Users/kimya/.pyenv/versions/3.7.3/lib/python3.7/site-packages/django/core/checks/urls.py", line 23, in check_resolver
    return check_method()
  File "/Users/kimya/.pyenv/versions/3.7.3/lib/python3.7/site-packages/django/urls/resolvers.py", line 412, in check
    for pattern in self.url_patterns:
  File "/Users/kimya/.pyenv/versions/3.7.3/lib/python3.7/site-packages/django/utils/functional.py", line 48, in __get__
    res = instance.__dict__[self.name] = self.func(instance)
  File "/Users/kimya/.pyenv/versions/3.7.3/lib/python3.7/site-packages/django/urls/resolvers.py", line 598, in url_patterns
    patterns = getattr(self.urlconf_module, "urlpatterns", self.urlconf_module)
  File "/Users/kimya/.pyenv/versions/3.7.3/lib/python3.7/site-packages/django/utils/functional.py", line 48, in __get__
    res = instance.__dict__[self.name] = self.func(instance)
  File "/Users/kimya/.pyenv/versions/3.7.3/lib/python3.7/site-packages/django/urls/resolvers.py", line 591, in urlconf_module
    return import_module(self.urlconf_name)
  File "/Users/kimya/.pyenv/versions/3.7.3/lib/python3.7/importlib/__init__.py", line 127, in import_module
    return _bootstrap._gcd_import(name[level:], package, level)
  File "<frozen importlib._bootstrap>", line 1006, in _gcd_import
  File "<frozen importlib._bootstrap>", line 983, in _find_and_load
  File "<frozen importlib._bootstrap>", line 967, in _find_and_load_unlocked
  File "<frozen importlib._bootstrap>", line 677, in _load_unlocked
  File "<frozen importlib._bootstrap_external>", line 728, in exec_module
  File "<frozen importlib._bootstrap>", line 219, in _call_with_frames_removed
  File "/Users/kimya/Documents/GitHub/Predix/predix/urls.py", line 23, in <module>
    path('crypto/', include('crypto.urls')),
  File "/Users/kimya/.pyenv/versions/3.7.3/lib/python3.7/site-packages/django/urls/conf.py", line 34, in include
    urlconf_module = import_module(urlconf_module)
  File "/Users/kimya/.pyenv/versions/3.7.3/lib/python3.7/importlib/__init__.py", line 127, in import_module
    return _bootstrap._gcd_import(name[level:], package, level)
  File "<frozen importlib._bootstrap>", line 1006, in _gcd_import
  File "<frozen importlib._bootstrap>", line 983, in _find_and_load
  File "<frozen importlib._bootstrap>", line 967, in _find_and_load_unlocked
  File "<frozen importlib._bootstrap>", line 677, in _load_unlocked
  File "<frozen importlib._bootstrap_external>", line 728, in exec_module
  File "<frozen importlib._bootstrap>", line 219, in _call_with_frames_removed
  File "/Users/kimya/Documents/GitHub/Predix/crypto/urls.py", line 5, in <module>
    from . import views
  File "/Users/kimya/Documents/GitHub/Predix/crypto/views.py", line 125
    liked = False
    ^
IndentationError: unexpected indent
Traceback (most recent call last):
  File "/Users/kimya/Documents/GitHub/Predix/manage.py", line 22, in <module>
    main()
  File "/Users/kimya/Documents/GitHub/Predix/manage.py", line 18, in main
    execute_from_command_line(sys.argv)
  File "/Users/kimya/.pyenv/versions/3.7.3/lib/python3.7/site-packages/django/core/management/__init__.py", line 419, in execute_from_command_line
    utility.execute()
  File "/Users/kimya/.pyenv/versions/3.7.3/lib/python3.7/site-packages/django/core/management/__init__.py", line 413, in execute
    self.fetch_command(subcommand).run_from_argv(self.argv)
  File "/Users/kimya/.pyenv/versions/3.7.3/lib/python3.7/site-packages/django/core/management/base.py", line 354, in run_from_argv
    self.execute(*args, **cmd_options)
  File "/Users/kimya/.pyenv/versions/3.7.3/lib/python3.7/site-packages/django/core/management/base.py", line 393, in execute
    self.check()
  File "/Users/kimya/.pyenv/versions/3.7.3/lib/python3.7/site-packages/django/core/management/base.py", line 423, in check
    databases=databases,
  File "/Users/kimya/.pyenv/versions/3.7.3/lib/python3.7/site-packages/django/core/checks/registry.py", line 76, in run_checks
    new_errors = check(app_configs=app_configs, databases=databases)
  File "/Users/kimya/.pyenv/versions/3.7.3/lib/python3.7/site-packages/django/core/checks/urls.py", line 13, in check_url_config
    return check_resolver(resolver)
  File "/Users/kimya/.pyenv/versions/3.7.3/lib/python3.7/site-packages/django/core/checks/urls.py", line 23, in check_resolver
    return check_method()
  File "/Users/kimya/.pyenv/versions/3.7.3/lib/python3.7/site-packages/django/urls/resolvers.py", line 412, in check
    for pattern in self.url_patterns:
  File "/Users/kimya/.pyenv/versions/3.7.3/lib/python3.7/site-packages/django/utils/functional.py", line 48, in __get__
    res = instance.__dict__[self.name] = self.func(instance)
  File "/Users/kimya/.pyenv/versions/3.7.3/lib/python3.7/site-packages/django/urls/resolvers.py", line 598, in url_patterns
    patterns = getattr(self.urlconf_module, "urlpatterns", self.urlconf_module)
  File "/Users/kimya/.pyenv/versions/3.7.3/lib/python3.7/site-packages/django/utils/functional.py", line 48, in __get__
    res = instance.__dict__[self.name] = self.func(instance)
  File "/Users/kimya/.pyenv/versions/3.7.3/lib/python3.7/site-packages/django/urls/resolvers.py", line 591, in urlconf_module
    return import_module(self.urlconf_name)
  File "/Users/kimya/.pyenv/versions/3.7.3/lib/python3.7/importlib/__init__.py", line 127, in import_module
    return _bootstrap._gcd_import(name[level:], package, level)
  File "<frozen importlib._bootstrap>", line 1006, in _gcd_import
  File "<frozen importlib._bootstrap>", line 983, in _find_and_load
  File "<frozen importlib._bootstrap>", line 967, in _find_and_load_unlocked
  File "<frozen importlib._bootstrap>", line 677, in _load_unlocked
  File "<frozen importlib._bootstrap_external>", line 728, in exec_module
  File "<frozen importlib._bootstrap>", line 219, in _call_with_frames_removed
  File "/Users/kimya/Documents/GitHub/Predix/predix/urls.py", line 23, in <module>
    path('crypto/', include('crypto.urls')),
  File "/Users/kimya/.pyenv/versions/3.7.3/lib/python3.7/site-packages/django/urls/conf.py", line 34, in include
    urlconf_module = import_module(urlconf_module)
  File "/Users/kimya/.pyenv/versions/3.7.3/lib/python3.7/importlib/__init__.py", line 127, in import_module
    return _bootstrap._gcd_import(name[level:], package, level)
  File "<frozen importlib._bootstrap>", line 1006, in _gcd_import
  File "<frozen importlib._bootstrap>", line 983, in _find_and_load
  File "<frozen importlib._bootstrap>", line 967, in _find_and_load_unlocked
  File "<frozen importlib._bootstrap>", line 677, in _load_unlocked
  File "<frozen importlib._bootstrap_external>", line 728, in exec_module
  File "<frozen importlib._bootstrap>", line 219, in _call_with_frames_removed
  File "/Users/kimya/Documents/GitHub/Predix/crypto/urls.py", line 5, in <module>
    from . import views
  File "/Users/kimya/Documents/GitHub/Predix/crypto/views.py", line 125
    liked = False
    ^
IndentationError: unexpected indent
Traceback (most recent call last):
  File "/Users/kimya/Documents/GitHub/Predix/manage.py", line 22, in <module>
    main()
  File "/Users/kimya/Documents/GitHub/Predix/manage.py", line 18, in main
    execute_from_command_line(sys.argv)
  File "/Users/kimya/.pyenv/versions/3.7.3/lib/python3.7/site-packages/django/core/management/__init__.py", line 419, in execute_from_command_line
    utility.execute()
  File "/Users/kimya/.pyenv/versions/3.7.3/lib/python3.7/site-packages/django/core/management/__init__.py", line 413, in execute
    self.fetch_command(subcommand).run_from_argv(self.argv)
  File "/Users/kimya/.pyenv/versions/3.7.3/lib/python3.7/site-packages/django/core/management/base.py", line 354, in run_from_argv
    self.execute(*args, **cmd_options)
  File "/Users/kimya/.pyenv/versions/3.7.3/lib/python3.7/site-packages/django/core/management/base.py", line 393, in execute
    self.check()
  File "/Users/kimya/.pyenv/versions/3.7.3/lib/python3.7/site-packages/django/core/management/base.py", line 423, in check
    databases=databases,
  File "/Users/kimya/.pyenv/versions/3.7.3/lib/python3.7/site-packages/django/core/checks/registry.py", line 76, in run_checks
    new_errors = check(app_configs=app_configs, databases=databases)
  File "/Users/kimya/.pyenv/versions/3.7.3/lib/python3.7/site-packages/django/core/checks/urls.py", line 13, in check_url_config
    return check_resolver(resolver)
  File "/Users/kimya/.pyenv/versions/3.7.3/lib/python3.7/site-packages/django/core/checks/urls.py", line 23, in check_resolver
    return check_method()
  File "/Users/kimya/.pyenv/versions/3.7.3/lib/python3.7/site-packages/django/urls/resolvers.py", line 412, in check
    for pattern in self.url_patterns:
  File "/Users/kimya/.pyenv/versions/3.7.3/lib/python3.7/site-packages/django/utils/functional.py", line 48, in __get__
    res = instance.__dict__[self.name] = self.func(instance)
  File "/Users/kimya/.pyenv/versions/3.7.3/lib/python3.7/site-packages/django/urls/resolvers.py", line 598, in url_patterns
    patterns = getattr(self.urlconf_module, "urlpatterns", self.urlconf_module)
  File "/Users/kimya/.pyenv/versions/3.7.3/lib/python3.7/site-packages/django/utils/functional.py", line 48, in __get__
    res = instance.__dict__[self.name] = self.func(instance)
  File "/Users/kimya/.pyenv/versions/3.7.3/lib/python3.7/site-packages/django/urls/resolvers.py", line 591, in urlconf_module
    return import_module(self.urlconf_name)
  File "/Users/kimya/.pyenv/versions/3.7.3/lib/python3.7/importlib/__init__.py", line 127, in import_module
    return _bootstrap._gcd_import(name[level:], package, level)
  File "<frozen importlib._bootstrap>", line 1006, in _gcd_import
  File "<frozen importlib._bootstrap>", line 983, in _find_and_load
  File "<frozen importlib._bootstrap>", line 967, in _find_and_load_unlocked
  File "<frozen importlib._bootstrap>", line 677, in _load_unlocked
  File "<frozen importlib._bootstrap_external>", line 728, in exec_module
  File "<frozen importlib._bootstrap>", line 219, in _call_with_frames_removed
  File "/Users/kimya/Documents/GitHub/Predix/predix/urls.py", line 23, in <module>
    path('crypto/', include('crypto.urls')),
  File "/Users/kimya/.pyenv/versions/3.7.3/lib/python3.7/site-packages/django/urls/conf.py", line 34, in include
    urlconf_module = import_module(urlconf_module)
  File "/Users/kimya/.pyenv/versions/3.7.3/lib/python3.7/importlib/__init__.py", line 127, in import_module
    return _bootstrap._gcd_import(name[level:], package, level)
  File "<frozen importlib._bootstrap>", line 1006, in _gcd_import
  File "<frozen importlib._bootstrap>", line 983, in _find_and_load
  File "<frozen importlib._bootstrap>", line 967, in _find_and_load_unlocked
  File "<frozen importlib._bootstrap>", line 677, in _load_unlocked
  File "<frozen importlib._bootstrap_external>", line 728, in exec_module
  File "<frozen importlib._bootstrap>", line 219, in _call_with_frames_removed
  File "/Users/kimya/Documents/GitHub/Predix/crypto/urls.py", line 5, in <module>
    from . import views
  File "/Users/kimya/Documents/GitHub/Predix/crypto/views.py", line 125
    liked = False
    ^
IndentationError: unexpected indent
Traceback (most recent call last):
  File "/Users/kimya/Documents/GitHub/Predix/manage.py", line 22, in <module>
    main()
  File "/Users/kimya/Documents/GitHub/Predix/manage.py", line 18, in main
    execute_from_command_line(sys.argv)
  File "/Users/kimya/.pyenv/versions/3.7.3/lib/python3.7/site-packages/django/core/management/__init__.py", line 419, in execute_from_command_line
    utility.execute()
  File "/Users/kimya/.pyenv/versions/3.7.3/lib/python3.7/site-packages/django/core/management/__init__.py", line 413, in execute
    self.fetch_command(subcommand).run_from_argv(self.argv)
  File "/Users/kimya/.pyenv/versions/3.7.3/lib/python3.7/site-packages/django/core/management/base.py", line 354, in run_from_argv
    self.execute(*args, **cmd_options)
  File "/Users/kimya/.pyenv/versions/3.7.3/lib/python3.7/site-packages/django/core/management/base.py", line 393, in execute
    self.check()
  File "/Users/kimya/.pyenv/versions/3.7.3/lib/python3.7/site-packages/django/core/management/base.py", line 423, in check
    databases=databases,
  File "/Users/kimya/.pyenv/versions/3.7.3/lib/python3.7/site-packages/django/core/checks/registry.py", line 76, in run_checks
    new_errors = check(app_configs=app_configs, databases=databases)
  File "/Users/kimya/.pyenv/versions/3.7.3/lib/python3.7/site-packages/django/core/checks/urls.py", line 13, in check_url_config
    return check_resolver(resolver)
  File "/Users/kimya/.pyenv/versions/3.7.3/lib/python3.7/site-packages/django/core/checks/urls.py", line 23, in check_resolver
    return check_method()
  File "/Users/kimya/.pyenv/versions/3.7.3/lib/python3.7/site-packages/django/urls/resolvers.py", line 412, in check
    for pattern in self.url_patterns:
  File "/Users/kimya/.pyenv/versions/3.7.3/lib/python3.7/site-packages/django/utils/functional.py", line 48, in __get__
    res = instance.__dict__[self.name] = self.func(instance)
  File "/Users/kimya/.pyenv/versions/3.7.3/lib/python3.7/site-packages/django/urls/resolvers.py", line 598, in url_patterns
    patterns = getattr(self.urlconf_module, "urlpatterns", self.urlconf_module)
  File "/Users/kimya/.pyenv/versions/3.7.3/lib/python3.7/site-packages/django/utils/functional.py", line 48, in __get__
    res = instance.__dict__[self.name] = self.func(instance)
  File "/Users/kimya/.pyenv/versions/3.7.3/lib/python3.7/site-packages/django/urls/resolvers.py", line 591, in urlconf_module
    return import_module(self.urlconf_name)
  File "/Users/kimya/.pyenv/versions/3.7.3/lib/python3.7/importlib/__init__.py", line 127, in import_module
    return _bootstrap._gcd_import(name[level:], package, level)
  File "<frozen importlib._bootstrap>", line 1006, in _gcd_import
  File "<frozen importlib._bootstrap>", line 983, in _find_and_load
  File "<frozen importlib._bootstrap>", line 967, in _find_and_load_unlocked
  File "<frozen importlib._bootstrap>", line 677, in _load_unlocked
  File "<frozen importlib._bootstrap_external>", line 728, in exec_module
  File "<frozen importlib._bootstrap>", line 219, in _call_with_frames_removed
  File "/Users/kimya/Documents/GitHub/Predix/predix/urls.py", line 23, in <module>
    path('crypto/', include('crypto.urls')),
  File "/Users/kimya/.pyenv/versions/3.7.3/lib/python3.7/site-packages/django/urls/conf.py", line 34, in include
    urlconf_module = import_module(urlconf_module)
  File "/Users/kimya/.pyenv/versions/3.7.3/lib/python3.7/importlib/__init__.py", line 127, in import_module
    return _bootstrap._gcd_import(name[level:], package, level)
  File "<frozen importlib._bootstrap>", line 1006, in _gcd_import
  File "<frozen importlib._bootstrap>", line 983, in _find_and_load
  File "<frozen importlib._bootstrap>", line 967, in _find_and_load_unlocked
  File "<frozen importlib._bootstrap>", line 677, in _load_unlocked
  File "<frozen importlib._bootstrap_external>", line 728, in exec_module
  File "<frozen importlib._bootstrap>", line 219, in _call_with_frames_removed
  File "/Users/kimya/Documents/GitHub/Predix/crypto/urls.py", line 5, in <module>
    from . import views
  File "/Users/kimya/Documents/GitHub/Predix/crypto/views.py", line 125
    liked = False
    ^
IndentationError: unexpected indent
Traceback (most recent call last):
  File "/Users/kimya/Documents/GitHub/Predix/manage.py", line 22, in <module>
    main()
  File "/Users/kimya/Documents/GitHub/Predix/manage.py", line 18, in main
    execute_from_command_line(sys.argv)
  File "/Users/kimya/.pyenv/versions/3.7.3/lib/python3.7/site-packages/django/core/management/__init__.py", line 419, in execute_from_command_line
    utility.execute()
  File "/Users/kimya/.pyenv/versions/3.7.3/lib/python3.7/site-packages/django/core/management/__init__.py", line 413, in execute
    self.fetch_command(subcommand).run_from_argv(self.argv)
  File "/Users/kimya/.pyenv/versions/3.7.3/lib/python3.7/site-packages/django/core/management/base.py", line 354, in run_from_argv
    self.execute(*args, **cmd_options)
  File "/Users/kimya/.pyenv/versions/3.7.3/lib/python3.7/site-packages/django/core/management/base.py", line 393, in execute
    self.check()
  File "/Users/kimya/.pyenv/versions/3.7.3/lib/python3.7/site-packages/django/core/management/base.py", line 423, in check
    databases=databases,
  File "/Users/kimya/.pyenv/versions/3.7.3/lib/python3.7/site-packages/django/core/checks/registry.py", line 76, in run_checks
    new_errors = check(app_configs=app_configs, databases=databases)
  File "/Users/kimya/.pyenv/versions/3.7.3/lib/python3.7/site-packages/django/core/checks/urls.py", line 13, in check_url_config
    return check_resolver(resolver)
  File "/Users/kimya/.pyenv/versions/3.7.3/lib/python3.7/site-packages/django/core/checks/urls.py", line 23, in check_resolver
    return check_method()
  File "/Users/kimya/.pyenv/versions/3.7.3/lib/python3.7/site-packages/django/urls/resolvers.py", line 412, in check
    for pattern in self.url_patterns:
  File "/Users/kimya/.pyenv/versions/3.7.3/lib/python3.7/site-packages/django/utils/functional.py", line 48, in __get__
    res = instance.__dict__[self.name] = self.func(instance)
  File "/Users/kimya/.pyenv/versions/3.7.3/lib/python3.7/site-packages/django/urls/resolvers.py", line 598, in url_patterns
    patterns = getattr(self.urlconf_module, "urlpatterns", self.urlconf_module)
  File "/Users/kimya/.pyenv/versions/3.7.3/lib/python3.7/site-packages/django/utils/functional.py", line 48, in __get__
    res = instance.__dict__[self.name] = self.func(instance)
  File "/Users/kimya/.pyenv/versions/3.7.3/lib/python3.7/site-packages/django/urls/resolvers.py", line 591, in urlconf_module
    return import_module(self.urlconf_name)
  File "/Users/kimya/.pyenv/versions/3.7.3/lib/python3.7/importlib/__init__.py", line 127, in import_module
    return _bootstrap._gcd_import(name[level:], package, level)
  File "<frozen importlib._bootstrap>", line 1006, in _gcd_import
  File "<frozen importlib._bootstrap>", line 983, in _find_and_load
  File "<frozen importlib._bootstrap>", line 967, in _find_and_load_unlocked
  File "<frozen importlib._bootstrap>", line 677, in _load_unlocked
  File "<frozen importlib._bootstrap_external>", line 728, in exec_module
  File "<frozen importlib._bootstrap>", line 219, in _call_with_frames_removed
  File "/Users/kimya/Documents/GitHub/Predix/predix/urls.py", line 23, in <module>
    path('crypto/', include('crypto.urls')),
  File "/Users/kimya/.pyenv/versions/3.7.3/lib/python3.7/site-packages/django/urls/conf.py", line 34, in include
    urlconf_module = import_module(urlconf_module)
  File "/Users/kimya/.pyenv/versions/3.7.3/lib/python3.7/importlib/__init__.py", line 127, in import_module
    return _bootstrap._gcd_import(name[level:], package, level)
  File "<frozen importlib._bootstrap>", line 1006, in _gcd_import
  File "<frozen importlib._bootstrap>", line 983, in _find_and_load
  File "<frozen importlib._bootstrap>", line 967, in _find_and_load_unlocked
  File "<frozen importlib._bootstrap>", line 677, in _load_unlocked
  File "<frozen importlib._bootstrap_external>", line 728, in exec_module
  File "<frozen importlib._bootstrap>", line 219, in _call_with_frames_removed
  File "/Users/kimya/Documents/GitHub/Predix/crypto/urls.py", line 19, in <module>
    path('fav/<int:pk>', FavCoinView, name='fav_coin'),
NameError: name 'FavCoinView' is not defined
Traceback (most recent call last):
  File "/Users/kimya/Documents/GitHub/Predix/manage.py", line 22, in <module>
    main()
  File "/Users/kimya/Documents/GitHub/Predix/manage.py", line 18, in main
    execute_from_command_line(sys.argv)
  File "/Users/kimya/.pyenv/versions/3.7.3/lib/python3.7/site-packages/django/core/management/__init__.py", line 419, in execute_from_command_line
    utility.execute()
  File "/Users/kimya/.pyenv/versions/3.7.3/lib/python3.7/site-packages/django/core/management/__init__.py", line 413, in execute
    self.fetch_command(subcommand).run_from_argv(self.argv)
  File "/Users/kimya/.pyenv/versions/3.7.3/lib/python3.7/site-packages/django/core/management/base.py", line 354, in run_from_argv
    self.execute(*args, **cmd_options)
  File "/Users/kimya/.pyenv/versions/3.7.3/lib/python3.7/site-packages/django/core/management/base.py", line 393, in execute
    self.check()
  File "/Users/kimya/.pyenv/versions/3.7.3/lib/python3.7/site-packages/django/core/management/base.py", line 423, in check
    databases=databases,
  File "/Users/kimya/.pyenv/versions/3.7.3/lib/python3.7/site-packages/django/core/checks/registry.py", line 76, in run_checks
    new_errors = check(app_configs=app_configs, databases=databases)
  File "/Users/kimya/.pyenv/versions/3.7.3/lib/python3.7/site-packages/django/core/checks/urls.py", line 13, in check_url_config
    return check_resolver(resolver)
  File "/Users/kimya/.pyenv/versions/3.7.3/lib/python3.7/site-packages/django/core/checks/urls.py", line 23, in check_resolver
    return check_method()
  File "/Users/kimya/.pyenv/versions/3.7.3/lib/python3.7/site-packages/django/urls/resolvers.py", line 412, in check
    for pattern in self.url_patterns:
  File "/Users/kimya/.pyenv/versions/3.7.3/lib/python3.7/site-packages/django/utils/functional.py", line 48, in __get__
    res = instance.__dict__[self.name] = self.func(instance)
  File "/Users/kimya/.pyenv/versions/3.7.3/lib/python3.7/site-packages/django/urls/resolvers.py", line 598, in url_patterns
    patterns = getattr(self.urlconf_module, "urlpatterns", self.urlconf_module)
  File "/Users/kimya/.pyenv/versions/3.7.3/lib/python3.7/site-packages/django/utils/functional.py", line 48, in __get__
    res = instance.__dict__[self.name] = self.func(instance)
  File "/Users/kimya/.pyenv/versions/3.7.3/lib/python3.7/site-packages/django/urls/resolvers.py", line 591, in urlconf_module
    return import_module(self.urlconf_name)
  File "/Users/kimya/.pyenv/versions/3.7.3/lib/python3.7/importlib/__init__.py", line 127, in import_module
    return _bootstrap._gcd_import(name[level:], package, level)
  File "<frozen importlib._bootstrap>", line 1006, in _gcd_import
  File "<frozen importlib._bootstrap>", line 983, in _find_and_load
  File "<frozen importlib._bootstrap>", line 967, in _find_and_load_unlocked
  File "<frozen importlib._bootstrap>", line 677, in _load_unlocked
  File "<frozen importlib._bootstrap_external>", line 728, in exec_module
  File "<frozen importlib._bootstrap>", line 219, in _call_with_frames_removed
  File "/Users/kimya/Documents/GitHub/Predix/predix/urls.py", line 23, in <module>
    path('crypto/', include('crypto.urls')),
  File "/Users/kimya/.pyenv/versions/3.7.3/lib/python3.7/site-packages/django/urls/conf.py", line 34, in include
    urlconf_module = import_module(urlconf_module)
  File "/Users/kimya/.pyenv/versions/3.7.3/lib/python3.7/importlib/__init__.py", line 127, in import_module
    return _bootstrap._gcd_import(name[level:], package, level)
  File "<frozen importlib._bootstrap>", line 1006, in _gcd_import
  File "<frozen importlib._bootstrap>", line 983, in _find_and_load
  File "<frozen importlib._bootstrap>", line 967, in _find_and_load_unlocked
  File "<frozen importlib._bootstrap>", line 677, in _load_unlocked
  File "<frozen importlib._bootstrap_external>", line 728, in exec_module
  File "<frozen importlib._bootstrap>", line 219, in _call_with_frames_removed
  File "/Users/kimya/Documents/GitHub/Predix/crypto/urls.py", line 19, in <module>
    path('fav/<int:pk>', FavCoinView, name='fav_coin'),
NameError: name 'FavCoinView' is not defined
